Workbook

Sheet Sheet1
A4: DATE | B4: 증권 평균 | C4: 은행 평균 | D4: 생보 평균 | E4: 손보 평균 | F4: 저축 평균 | G4: 원리금보장상품금리 평균 (1년, DB) | H4: 국채금리 (1년) | I4: 기준금리
A5: 2012-02-01 | B5: 4.885 | C5: 4.6325 | D5: 4.8223077 | E5: 4.825 | G5: =AVERAGE(B5:E5) -> 4.7912019 | H5: 3.38 | I5: 3.25 | J5: =B5-I5 -> 1.635
A6: 2012-02-16 | B6: 4.845 | C6: 4.675625 | D6: 4.7007692 | E6: 4.80125 | G6: =AVERAGE(B6:E6) -> 4.7556611 | H6: 3.4 | I6: 3.25 | J6: =B6-I6 -> 1.595
A7: 2012-03-01 | B7: 4.8466667 | C7: 4.625625 | D7: 4.6838462 | E7: 4.825 | G7: =AVERAGE(B7:E7) -> 4.7452845 | H7: 3.45 | I7: 3.25 | J7: =B7-I7 -> 1.5966667
A8: 2012-03-16 | B8: 4.86 | C8: 4.651875 | D8: 4.6846154 | E8: 4.8175 | G8: =AVERAGE(B8:E8) -> 4.7534976 | H8: 3.51 | I8: 3.25 | J8: =B8-I8 -> 1.61
A9: 2012-04-01 | B9: 4.9125 | C9: 4.69625 | D9: 4.6869231 | E9: 4.8125 | G9: =AVERAGE(B9:E9) -> 4.7770433 | H9: 3.48 | I9: 3.25 | J9: =B9-I9 -> 1.6625
A10: 2012-04-16 | B10: 4.8825 | C10: 4.6576471 | D10: 4.7007692 | E10: 4.82375 | G10: =AVERAGE(B10:E10) -> 4.7661666 | H10: 3.43 | I10: 3.25 | J10: =B10-I10 -> 1.6325
A11: 2012-05-01 | B11: 4.7791667 | C11: 4.6282353 | D11: 4.6192308 | E11: 4.77125 | G11: =AVERAGE(B11:E11) -> 4.6994707 | H11: 3.43 | I11: 3.25 | J11: =B11-I11 -> 1.5291667
A12: 2012-05-16 | B12: 4.6983333 | C12: 4.6141176 | D12: 4.5623077 | E12: 4.7225 | G12: =AVERAGE(B12:E12) -> 4.6493147 | H12: 3.37 | I12: 3.25 | J12: =B12-I12 -> 1.4483333
A13: 2012-06-01 | B13: 4.6158333 | C13: 4.59 | D13: 4.4861538 | E13: 4.62125 | G13: =AVERAGE(B13:E13) -> 4.5783093 | H13: 3.3 | I13: 3.25 | J13: =B13-I13 -> 1.3658333
A14: 2012-06-16 | B14: 4.5616667 | C14: 4.555 | D14: 4.4176923 | E14: 4.565 | G14: =AVERAGE(B14:E14) -> 4.5248397 | H14: 3.3 | I14: 3.25 | J14: =B14-I14 -> 1.3116667
A15: 2012-07-01 | B15: 4.5708333 | C15: 4.514375 | D15: 4.3969231 | E15: 4.45625 | G15: =AVERAGE(B15:E15) -> 4.4845954 | H15: 3.31 | I15: 3 | J15: =B15-I15 -> 1.5708333
A16: 2012-07-16 | B16: 4.5741667 | C16: 4.43625 | D16: 4.3969231 | E16: 4.4675 | G16: =AVERAGE(B16:E16) -> 4.4687099 | H16: 2.97 | I16: 3 | J16: =B16-I16 -> 1.5741667
... A72: 2014-12-01 | B72: 3.01 | C72: 2.39 | D72: 2.82 | E72: 2.95 | G72: =AVERAGE(B72:E72) -> 2.7925 | H72: 2.012 | I72: 2 | J72: =B72-I72 -> 1.01
A73: 42005 | B73: 2.96 | C73: 2.39 | D73: 2.74 | E73: 2.85 | G73: =AVERAGE(B73:E73) -> 2.735 | H73: 2.074 | I73: 2 | J73: =B73-I73 -> 0.96
A74: 42036 | B74: 2.86 | C74: 2.23 | D74: 2.65 | E74: 2.76 | G74: =AVERAGE(B74:E74) -> 2.625 | H74: 1.967 | I74: 2 | J74: =B74-I74 -> 0.86
A75: 42064 | B75: 2.82 | C75: 2.23 | D75: 2.61 | E75: 2.72 | G75: =AVERAGE(B75:E75) -> 2.595 | H75: 1.979 | I75: 1.75 | J75: =B75-I75 -> 1.07
A76: 42095 | B76: 2.6 | C76: 2.01 | D76: 2.54 | E76: 2.61 | G76: =AVERAGE(B76:E76) -> 2.44 | H76: 1.76 | I76: 1.75 | J76: =B76-I76 -> 0.85
A77: 42125 | B77: 2.55 | C77: 1.92 | D77: 2.45 | E77: 2.51 | G77: =AVERAGE(B77:E77) -> 2.3575 | H77: 1.762 | I77: 1.75 | J77: =B77-I77 -> 0.8
A78: 42156 | B78: 2.58 | C78: 1.95 | D78: 2.47 | E78: 2.5 | G78: =AVERAGE(B78:E78) -> 2.375 | H78: 1.66 | I78: 1.5 | J78: =B78-I78 -> 1.08
A79: 42186 | B79: 2.32 | C79: 1.81 | D79: 2.47 | E79: 2.47 | G79: =AVERAGE(B79:E79) -> 2.2675 | H79: 1.613 | I79: 1.5 | J79: =B79-I79 -> 0.82
A80: 42217 | B80: 2.25 | C80: 1.75 | D80: 2.43 | E80: 2.44 | G80: =AVERAGE(B80:E80) -> 2.2175 | H80: 1.601 | I80: 1.5 | J80: =B80-I80 -> 0.75
A81: 42248 | B81: 2.23 | C81: 1.75 | D81: 2.4 | E81: 2.38 | G81: =AVERAGE(B81:E81) -> 2.19 | H81: 1.589 | I81: 1.5 | J81: =B81-I81 -> 0.73
A82: 42278 | B82: 2.2 | C82: 1.73 | D82: 2.37 | E82: 2.36 | G82: =AVERAGE(B82:E82) -> 2.165 | H82: 1.589 | I82: 1.5 | J82: =B82-I82 -> 0.7
A83: 42309 | B83: 2.25 | C83: 1.74 | D83: 2.34 | E83: 2.33 | G83: =AVERAGE(B83:E83) -> 2.165 | H83: 1.576 | I83: 1.5 | J83: =B83-I83 -> 0.75
A84: 42339 | B84: 2.4 | C84: 1.87 | D84: 2.4 | E84: 2.4 | G84: =AVERAGE(B84:E84) -> 2.2675 | H84: 1.654 | I84: 1.5 | J84: =B84-I84 -> 0.9
... A110: 43132 | B110: 2.04 | C110: 1.69 | D110: 2.06 | E110: 2.15 | G110: =AVERAGE(B110:E110) -> 1.985 | H110: 1.852 | I110: 1.5 | J110: =B110-I110 -> 0.54
A111: 43160 | B111: ='[1]2018.3.1~31'!B22 -> 0 | C111: ='[1]2018.3.1~31'!B40 -> 0 | D111: ='[1]2018.3.1~31'!B55 -> 0 | E111: ='[1]2018.3.1~31'!B64 -> 0 | G111: =AVERAGE(B111:E111) -> 0 | H111: 1.875 | I111: 1.5 | J111: =B111-I111 -> -1.5
A112: 43191 | B112: ='[1]2018.4.1~30'!B22 -> 0 | C112: ='[1]2018.4.1~30'!B40 -> 0 | D112: ='[1]2018.4.1~30'!B55 -> 0 | E112: ='[1]2018.4.1~30'!B64 -> 0 | G112: =AVERAGE(B112:E112) -> 0 | H112: 1.873 | I112: 1.5 | J112: =B112-I112 -> -1.5
A113: 43221 | B113: ='[1]2018.05'!B22 -> 0 | C113: ='[1]2018.05'!B40 -> 0 | D113: ='[1]2018.05'!B55 -> 0 | E113: ='[1]2018.05'!B64 -> 0 | G113: =AVERAGE(B113:E113) -> 0 | H113: 1.887 | I113: 1.5 | J113: =B113-I113 -> -1.5
A114: 43252 | B114: ='[1]2018.06'!B22 -> 0 | C114: ='[1]2018.06'!B40 -> 0 | D114: ='[1]2018.06'!B55 -> 0 | E114: ='[1]2018.06'!B64 -> 0 | G114: =AVERAGE(B114:E114) -> 0 | H114: 1.851 | I114: 1.5 | J114: =B114-I114 -> -1.5
A115: 43282 | B115: ='[1]2018.07'!B22 -> 0 | C115: ='[1]2018.07'!B39 -> 0 | D115: ='[1]2018.07'!B54 -> 0 | E115: ='[1]2018.07'!B63 -> 0 | G115: =AVERAGE(B115:E115) -> 0 | H115: 1.842 | I115: 1.5 | J115: =B115-I115 -> -1.5
A116: 43313 | B116: ='[1]2018.08'!B23 -> 0 | C116: ='[1]2018.08'!B40 -> 0 | D116: ='[1]2018.08'!B55 -> 0 | E116: ='[1]2018.08'!B64 -> 0 | G116: =AVERAGE(B116:E116) -> 0 | H116: 1.83 | I116: 1.5 | J116: =B116-I116 -> -1.5
A117: 43344 | B117: ='[1]2018.09'!B23 -> 0 | C117: ='[1]2018.09'!B40 -> 0 | D117: ='[1]2018.09'!B55 -> 0 | E117: ='[1]2018.09'!B64 -> 0 | G117: =AVERAGE(B117:E117) -> 0 | H117: 1.79 | I117: 1.5 | J117: =B117-I117 -> -1.5
A118: 43374 | B118: ='[1]2018.10'!B23 -> 0 | C118: ='[1]2018.10'!B40 -> 0 | D118: ='[1]2018.10'!B55 -> 0 | E118: ='[1]2018.10'!B64 -> 0 | G118: =AVERAGE(B118:E118) -> 0 | H118: 1.853 | I118: 1.5 | J118: =B118-I118 -> -1.5
A119: 43405 | B119: ='[1]2018.11'!B23 -> 0 | C119: ='[1]2018.11'!B40 -> 0 | D119: ='[1]2018.11'!B55 -> 0 | E119: ='[1]2018.11'!B64 -> 0 | G119: =AVERAGE(B119:E119) -> 0 | H119: 1.844 | I119: 1.5 | J119: =B119-I119 -> -1.5
A120: 43435 | B120: ='[1]2018.12'!B23 -> 0 | C120: ='[1]2018.12'!B40 -> 0 | D120: ='[1]2018.12'!B55 -> 0 | E120: ='[1]2018.12'!B64 -> 0 | G120: =AVERAGE(B120:E120) -> 0 | H120: 1.776 | I120: 1.75 | J120: =B120-I120 -> -1.75
A121: 43466 | B121: ='[1]2019.01'!B23 -> 0 | C121: ='[1]2019.01'!B40 -> 0 | D121: ='[1]2019.01'!B55 -> 0 | E121: ='[1]2019.01'!B64 -> 0 | G121: =AVERAGE(B121:E121) -> 0 | H121: 1.733 | I121: 1.75 | J121: =B121-I121 -> -1.75
A122: 43497 | B122: ='[1]2019.02'!B23 -> 0 | C122: ='[1]2019.02'!B40 -> 0 | D122: ='[1]2019.02'!C55 -> 평균 | E122: ='[1]2019.02'!B64 -> 0 | G122: =AVERAGE(B122:E122) -> 0 | H122: 1.76 | I122: 1.75 | J122: =B122-I122 -> -1.75
A123: 43525 | B123: ='[1]2019.03'!B22 -> 0 | C123: ='[1]2019.03'!B39 -> 0 | D123: ='[1]2019.03'!B53 -> 0 | E123: ='[1]2019.03'!B62 -> 0 | F123: ='[1]2019.03'!B85 -> 0 | G123: =AVERAGE(B123:E123) -> 0 | H123: 1.769 | I123: 1.75 | J123: =B123-I123 -> -1.75
...

Sheet Sheet2
A4: DATE | B4: 증권 평균 | C4: 은행 평균 | D4: 생보 평균 | E4: 손보 평균 | F4: 저축 평균 | G4: 원리금보장상품금리 평균 (1년, DB) | H4: 기준금리
A5: 2012-02-01 | B5: 4.885 | C5: 4.6325 | D5: 4.8223077 | E5: 4.825 | G5: 4.7912019 | H5: 3.25
A6: 2012-02-16 | B6: 4.845 | C6: 4.675625 | D6: 4.7007692 | E6: 4.80125 | G6: 4.7556611 | H6: 3.25
A7: 2012-03-01 | B7: 4.8466667 | C7: 4.625625 | D7: 4.6838462 | E7: 4.825 | G7: 4.7452845 | H7: 3.25
A8: 2012-03-16 | B8: 4.86 | C8: 4.651875 | D8: 4.6846154 | E8: 4.8175 | G8: 4.7534976 | H8: 3.25
A9: 2012-04-01 | B9: 4.9125 | C9: 4.69625 | D9: 4.6869231 | E9: 4.8125 | G9: 4.7770433 | H9: 3.25
A10: 2012-04-16 | B10: 4.8825 | C10: 4.6576471 | D10: 4.7007692 | E10: 4.82375 | G10: 4.7661666 | H10: 3.25
A11: 2012-05-01 | B11: 4.7791667 | C11: 4.6282353 | D11: 4.6192308 | E11: 4.77125 | G11: 4.6994707 | H11: 3.25
A12: 2012-05-16 | B12: 4.6983333 | C12: 4.6141176 | D12: 4.5623077 | E12: 4.7225 | G12: 4.6493147 | H12: 3.25
A13: 2012-06-01 | B13: 4.6158333 | C13: 4.59 | D13: 4.4861538 | E13: 4.62125 | G13: 4.5783093 | H13: 3.25
A14: 2012-06-16 | B14: 4.5616667 | C14: 4.555 | D14: 4.4176923 | E14: 4.565 | G14: 4.5248397 | H14: 3.25
A15: 2012-07-01 | B15: 4.5708333 | C15: 4.514375 | D15: 4.3969231 | E15: 4.45625 | G15: 4.4845954 | H15: 3
A16: 2012-07-16 | B16: 4.5741667 | C16: 4.43625 | D16: 4.3969231 | E16: 4.4675 | G16: 4.4687099 | H16: 3
... A72: 2014-12-01 | B72: 3.01 | C72: 2.39 | D72: 2.82 | E72: 2.95 | G72: 2.7925 | H72: 2
A73: 42005 | B73: 2.96 | C73: 2.39 | D73: 2.74 | E73: 2.85 | G73: 2.735 | H73: 2
A74: 42036 | B74: 2.86 | C74: 2.23 | D74: 2.65 | E74: 2.76 | G74: 2.625 | H74: 2
A75: 42064 | B75: 2.82 | C75: 2.23 | D75: 2.61 | E75: 2.72 | G75: 2.595 | H75: 1.75
A76: 42095 | B76: 2.6 | C76: 2.01 | D76: 2.54 | E76: 2.61 | G76: 2.44 | H76: 1.75
A77: 42125 | B77: 2.55 | C77: 1.92 | D77: 2.45 | E77: 2.51 | G77: 2.3575 | H77: 1.75
A78: 42156 | B78: 2.58 | C78: 1.95 | D78: 2.47 | E78: 2.5 | G78: 2.375 | H78: 1.5
A79: 42186 | B79: 2.32 | C79: 1.81 | D79: 2.47 | E79: 2.47 | G79: 2.2675 | H79: 1.5
A80: 42217 | B80: 2.25 | C80: 1.75 | D80: 2.43 | E80: 2.44 | G80: 2.2175 | H80: 1.5
A81: 42248 | B81: 2.23 | C81: 1.75 | D81: 2.4 | E81: 2.38 | G81: 2.19 | H81: 1.5
A82: 42278 | B82: 2.2 | C82: 1.73 | D82: 2.37 | E82: 2.36 | G82: 2.165 | H82: 1.5
A83: 42309 | B83: 2.25 | C83: 1.74 | D83: 2.34 | E83: 2.33 | G83: 2.165 | H83: 1.5
A84: 42339 | B84: 2.4 | C84: 1.87 | D84: 2.4 | E84: 2.4 | G84: 2.2675 | H84: 1.5
... A122: 43497 | B122: 2.356 | C122: 1.9878571 | D122: 2.1218182 | E122: 2.23 | G122: 2.1739188 | H122: 1.75
A123: 43525 | B123: 2.39 | C123: 2.0142857 | D123: 2.1827273 | E123: 2.235 | F123: 2.2833333 | G123: 2.2055032 | H123: 1.75
A124: 43556 | B124: 2.4163636 | C124: 2.0164286 | D124: 2.1945455 | E124: 2.2666667 | F124: 2.3028571 | G124: 2.2235011 | H124: 1.75
A125: 43586 | B125: 2.42 | C125: 1.9892308 | D125: 2.1863636 | E125: 2.2883333 | F125: 2.412 | G125: 2.2209819 | H125: 1.75
A126: 43617 | B126: 2.3941667 | C126: 1.9707143 | D126: 2.2490909 | E126: 2.3483333 | F126: 2.502 | G126: 2.2405763 | H126: 1.75
A127: 43647 | B127: 2.3053846 | C127: 1.8885714 | D127: 2.2716667 | E127: 2.2716667 | F127: 2.5618182 | G127: 2.1843223 | H127: 1.5
A128: 43678 | B128: 2.1946154 | C128: 1.6892857 | D128: 2.1409091 | E128: 2.255 | F128: 2.5836364 | G128: 2.0699525 | H128: 1.5
A129: 43709 | B129: 2.0516667 | C129: 1.585 | D129: 2.0672727 | E129: 2.16 | F129: 2.5836364 | G129: 1.9659848 | H129: 1.5
A130: 43739 | B130: 2.1166667 | C130: 1.7535714 | D130: 2.0736364 | E130: 2.1366667 | F130: 2.5390909 | G130: 2.0201353 | H130: 1.25
A131: 43770 | B131: 2.1325 | C131: 1.7328571 | D131: 2.0918182 | E131: 2.1066667 | F131: 2.4633333 | G131: 2.0159605 | H131: 1.25
A132: 43800 | B132: 2.2133333 | C132: 1.81 | D132: 2.1872727 | E132: 2.2583333 | F132: 2.425 | G132: 2.1172348 | H132: 1.25
A133: 43831 | B133: 2.1725 | C133: 1.7571429 | D133: 2.0936364 | E133: 2.1 | F133: 2.3471429 | G133: 2.0308198 | H133: 1.25
A134: 43862 | B134: 2.1466667 | C134: 1.6914286 | D134: 2.0509091 | E134: 2.1683333 | F134: 2.2266667 | G134: 2.0143344 | H134: 1.25
... A211: 46204 | B211: 3.8252381 | C211: 2.9258824 | D211: 2.8135714 | E211: 3.1357143 | F211: 4.1104762 | G211: 3.1751015 | H211: 2.5
